Workbook

Sheet Hoja1
A1: CAPITAL | B1: ASPECTO | C1: INDICE 2025 | D1: INDICE 2026
A2: Social | B2: Conocimientos de primeros auxilios | C2: A | D2: A
A3: Social | B3: Acción contra el cambio climático | C3: B | D3: B
A4: Social | B4: Concientización de la exposición a las inundaciones | C4: B | D4: A
A5: Social | B5: Conocimientos de seguridad y evacuación de inundaciones | C5: D | D5: B
A6: Humano | B6: Apoyo mutuo | C6: C | D6: C
A7: Humano | B7: Personal de respuesta a desastres | C7: C | D7: A
A8: Humano | B8: Planeación de reducción de riesgo | C8: D | D8: B
A9: Humano | B9: Mapeo de riesgos | C9: D | D9: A
A10: Fisico | B10: Alerta temprana | C10: D | D10: B
A11: Fisico | B11: Pronóstico de inundaciones | C11: A | D11: A
A12: Fisico | B12: Protección contra inundaciones domésticas | C12: C | D12: C
... A21: Financiero | B21: Presupuesto de recuperación de inundaciones | C21: B | D21: B

Sheet Hoja2
A1: CAPITAL | B1: ASPECTO | C1: AÑO | D1: INDICE | E1: PUNTUACION
A2: Social | B2: Conocimientos de primeros auxilios | C2: 2025 | D2: A | E2: 4
A3: Social | B3: Conocimientos de primeros auxilios | C3: 2026 | D3: A | E3: 4
A4: Social | B4: Concientización de la exposición a las inundaciones | C4: 2026 | D4: A | E4: 4
A5: Humano | B5: Personal de respuesta a desastres | C5: 2026 | D5: A | E5: 4
A6: Humano | B6: Mapeo de riesgos | C6: 2026 | D6: A | E6: 4
A7: Fisico | B7: Pronóstico de inundaciones | C7: 2025 | D7: =Hoja1!C11 -> A | E7: 4
A8: Fisico | B8: Pronóstico de inundaciones | C8: 2026 | D8: =Hoja1!D11 -> A | E8: 4
A9: Social | B9: Acción contra el cambio climático | C9: 2025 | D9: B | E9: 3
A10: Social | B10: Acción contra el cambio climático | C10: 2026 | D10: B | E10: 3
A11: Social | B11: Concientización de la exposición a las inundaciones | C11: 2025 | D11: B | E11: 3
A12: Social | B12: Conocimientos de seguridad y evacuación de inundaciones | C12: 2026 | D12: B | E12: 3
A13: Humano | B13: Planeación de reducción de riesgo | C13: 2026 | D13: B | E13: 3
A14: Fisico | B14: Alerta temprana | C14: 2026 | D14: =Hoja1!D10 -> B | E14: 3
A15: Natural | B15: Salud de la interfase tierra/agua | C15: 2026 | D15: =Hoja1!D16 -> B | E15: 3
A16: Natural | B16: Uso del capital natural para la gestión del riesgo de inundación | C16: 2026 | D16: =Hoja1!D17 -> B | E16: 3
A17: Financiero | B17: Inversiones en reducción de riesgos | C17: 2026 | D17: =Hoja1!D19 -> B | E17: 3
A18: Financiero | B18: Seguro contra inundaciones | C18: 2026 | D18: =Hoja1!D20 -> B | E18: 3
A19: Financiero | B19: Presupuesto de recuperación de inundaciones | C19: 2025 | D19: =Hoja1!C21 -> B | E19: 3
A20: Financiero | B20: Presupuesto de recuperación de inundaciones | C20: 2026 | D20: =Hoja1!D21 -> B | E20: 3
A21: Humano | B21: Apoyo mutuo | C21: 2025 | D21: C | E21: 2
A22: Humano | B22: Apoyo mutuo | C22: 2026 | D22: C | E22: 2
A23: Humano | B23: Personal de respuesta a desastres | C23: 2025 | D23: C | E23: 2
A24: Fisico | B24: Protección contra inundaciones domésticas | C24: 2025 | D24: =Hoja1!C12 -> C | E24: 2
A25: Fisico | B25: Protección contra inundaciones domésticas | C25: 2026 | D25: =Hoja1!D12 -> C | E25: 2
A26: Fisico | B26: Protección contra inundaciones a gran escala | C26: 2026 | D26: =Hoja1!D13 -> C | E26: 2
A27: Natural | B27: Cubierta arbórea | C27: 2026 | D27: =Hoja1!D14 -> C | E27: 2
A28: Natural | B28: Superficies permeables | C28: 2026 | D28: =Hoja1!D15 -> C | E28: 2
A29: Financiero | B29: Planificación e inversión en adaptación al cambio climático | C29: 2026 | D29: =Hoja1!D18 -> C | E29: 2
A30: Financiero | B30: Inversiones en reducción de riesgos | C30: 2025 | D30: =Hoja1!C19 -> C | E30: 2
A31: Social | B31: Conocimientos de seguridad y evacuación de inundaciones | C31: 2025 | D31: D | E31: 1
A32: Humano | B32: Planeación de reducción de riesgo | C32: 2025 | D32: D | E32: 1
A33: Humano | B33: Mapeo de riesgos | C33: 2025 | D33: D | E33: 1
A34: Fisico | B34: Alerta temprana | C34: 2025 | D34: =Hoja1!C10 -> D | E34: 1
A35: Fisico | B35: Protección contra inundaciones a gran escala | C35: 2025 | D35: =Hoja1!C13 -> D | E35: 1
A36: Natural | B36: Cubierta arbórea | C36: 2025 | D36: =Hoja1!C14 -> D | E36: 1
A37: Natural | B37: Superficies permeables | C37: 2025 | D37: =Hoja1!C15 -> D | E37: 1
A38: Natural | B38: Salud de la interfase tierra/agua | C38: 2025 | D38: =Hoja1!C16 -> D | E38: 1
A39: Natural | B39: Uso del capital natural para la gestión del riesgo de inundación | C39: 2025 | D39: =Hoja1!C17 -> D | E39: 1
A40: Financiero | B40: Planificación e inversión en adaptación al cambio climático | C40: 2025 | D40: =Hoja1!C18 -> D | E40: 1
...
